Workbook
Name TOTAL_B_ART1ro: #REF!
Name TOTAL_B_ART1ro: #REF!
Name TOTAL_B_ART1ro: #REF!
Name TOTAL_C_ART42: #REF!
Name TOTAL_C_ART42: #REF!
Name TOTAL_C_ART42: #REF!
Name TOTAL_D_ICTP: #REF!
Name TOTAL_D_ICTP: #REF!
Name TOTAL_D_ICTP: #REF!
Name TOTAL_E_PATENTE: #REF!
Name TOTAL_E_PATENTE: #REF!
Name TOTAL_E_PATENTE: #REF!
Name TOTAL_F_COSTOSADICIONALES: #REF!
Name TOTAL_F_COSTOSADICIONALES: #REF!
Name TOTAL_F_COSTOSADICIONALES: #REF!
Name TOTAL_G_MARCADETERMINADA: #REF!
Name TOTAL_G_MARCADETERMINADA: #REF!
Name TOTAL_G_MARCADETERMINADA: #REF!
Name TOTAL_H_OTROS: #REF!
Name TOTAL_H_OTROS: #REF!
Name TOTAL_H_OTROS: #REF!
Name TOTAL_I_LP: #REF!
Name TOTAL_I_LP: #REF!
Name TOTAL_I_LP: #REF!
Name TOTAL_PRESUPUESTO: #REF!
Name TOTAL_PRESUPUESTO: #REF!
Name TOTAL_PRESUPUESTO: #REF!

Sheet 30_70 (Miles)
A2: FO-70/30-01
A4: Cálculo y determinación del porcentaje del 30% a que se refiere el artículo 42 de
A5: la Ley de Adquisiciones, Arrendamientos y Servicios del Sector Público
A6: (Miles de pesos)
A7: Dependencia o Entidad: COMISION NACIONAL FORESTAL | I7: Periodo: del 01 de enero al 31 de marzo 2020
A9: CONCEPTO | C9: PRESUPUESTO ANUAL AUTORIZADO | D9: CONTRATACIONES FORMALIZADAS CON CONTRATO FIRMADO
D10: ENTRE DEPENDENCIAS Y ENTIDADES | E10: ARTÍCULO 42 | G10: ARTÍCULO 41 | K10: LICITACIÓN PÚBLICA
A12: CLAVE | B12: DESCRIPCIÓN | C12: (Incluye modificaciones, en su caso) | E12: ADJUDICACIÓN DIRECTA | F12: INVITACIÓN A CUANDO MENOS TRES PERSONAS | G12: PATENTE | H12: COSTOS ADICIONALES | I12: MARCA DETERMINADA | J12: OTROS
D13: (Párrafo quinto del art.1 de la Ley) | K13: (Arts. 26, 26 Bis y 28 de la Ley)
G14: I | H14: III | I14: VIII | J14: II, IV a VII y IX a XX
C15: (A) | D15: (B) | E15: (C) | F15: (D) | G15: (E) | H15: (F) | I15: (G) | J15: (H) | K15: (I)
A16: CAPÍTULO 2000 - MATERIALES Y SUMINISTROS | C16: =SUM(C17:C17) -> 0 | D16: =SUM(D17:D17) -> 0 | E16: =SUM(E17:E17) -> 0 | F16: =SUM(F17:F17) -> 0 | G16: =SUM(G17:G17) -> 0 | H16: =SUM(H17:H17) -> 0 | I16: =SUM(I17:I17) -> 0 | J16: =SUM(J17:J17) -> 0 | K16: =SUM(K17:K17) -> 0
C17: 0 | D17: 0 | E17: 0 | F17: 0 | G17: 0 | H17: 0 | I17: 0 | J17: 0 | K17: 0
C18: 0 | D18: 0 | E18: 0 | F18: 0 | G18: 0 | H18: 0 | I18: 0 | J18: 0 | K18: 0
C19: 0 | D19: 0 | E19: 0 | F19: 0 | G19: 0 | H19: 0 | I19: 0 | J19: 0 | K19: 0
C20: 0 | D20: 0 | E20: 0 | F20: 0 | G20: 0 | H20: 0 | I20: 0 | J20: 0 | K20: 0
C21: 0 | D21: 0 | E21: 0 | F21: 0 | G21: 0 | H21: 0 | I21: 0 | J21: 0 | K21: 0
C22: 0 | D22: 0 | E22: 0 | F22: 0 | G22: 0 | H22: 0 | I22: 0 | J22: 0 | K22: 0
C23: 0 | D23: 0 | E23: 0 | F23: 0 | G23: 0 | H23: 0 | I23: 0 | J23: 0 | K23: 0
C24: 0 | D24: 0 | E24: 0 | F24: 0 | G24: 0 | H24: 0 | I24: 0 | J24: 0 | K24: 0
C25: 0 | D25: 0 | E25: 0 | F25: 0 | G25: 0 | H25: 0 | I25: 0 | J25: 0 | K25: 0
A26: CAPÍTULO 3000 - SERVICIOS GENERALES (Excepto el Concepto 3900) | C26: =SUM(C27:C27) -> 0 | D26: =SUM(D27:D27) -> 0 | E26: =SUM(E27:E27) -> 0 | F26: =SUM(F27:F27) -> 0 | G26: =SUM(G27:G27) -> 0 | H26: =SUM(H27:H27) -> 0 | I26: =SUM(I27:I27) -> 0 | J26: =SUM(J27:J27) -> 0 | K26: =SUM(K27:K27) -> 0
C27: 0 | D27: 0 | E27: 0 | F27: 0 | G27: 0 | H27: 0 | I27: 0 | J27: 0 | K27: 0
C28: 0 | D28: 0 | E28: 0 | F28: 0 | G28: 0 | H28: 0 | I28: 0 | J28: 0 | K28: 0
C29: 0 | D29: 0 | E29: 0 | F29: 0 | G29: 0 | H29: 0 | I29: 0 | J29: 0 | K29: 0
C30: 0 | D30: 0 | E30: 0 | F30: 0 | G30: 0 | H30: 0 | I30: 0 | J30: 0 | K30: 0
C31: 0 | D31: 0 | E31: 0 | F31: 0 | G31: 0 | H31: 0 | I31: 0 | J31: 0 | K31: 0
C32: 0 | D32: 0 | E32: 0 | F32: 0 | G32: 0 | H32: 0 | I32: 0 | J32: 0 | K32: 0
C33: 0 | D33: 0 | E33: 0 | F33: 0 | G33: 0 | H33: 0 | I33: 0 | J33: 0 | K33: 0
C34: 0 | D34: 0 | E34: 0 | F34: 0 | G34: 0 | H34: 0 | I34: 0 | J34: 0 | K34: 0
A35: CAPÍTULO 5000 - BIENES MUEBLES, INMUEBLES E INTANGIBLES (Excepto el concepto 5800) | C35: =SUM(C36:C36) -> 0 | D35: =SUM(D36:D36) -> 0 | E35: =SUM(E36:E36) -> 0 | F35: =SUM(F36:F36) -> 0 | G35: =SUM(G36:G36) -> 0 | H35: =SUM(H36:H36) -> 0 | I35: =SUM(I36:I36) -> 0 | J35: =SUM(J36:J36) -> 0 | K35: =SUM(K36:K36) -> 0
C36: 0 | D36: 0 | E36: 0 | F36: 0 | G36: 0 | H36: 0 | I36: 0 | J36: 0 | K36: 0
C37: 0 | D37: 0 | E37: 0 | F37: 0 | G37: 0 | H37: 0 | I37: 0 | J37: 0 | K37: 0
C38: 0 | D38: 0 | E38: 0 | F38: 0 | G38: 0 | H38: 0 | I38: 0 | J38: 0 | K38: 0
C39: 0 | D39: 0 | E39: 0 | F39: 0 | G39: 0 | H39: 0 | I39: 0 | J39: 0 | K39: 0
C40: 0 | D40: 0 | E40: 0 | F40: 0 | G40: 0 | H40: 0 | I40: 0 | J40: 0 | K40: 0
C41: 0 | D41: 0 | E41: 0 | F41: 0 | G41: 0 | H41: 0 | I41: 0 | J41: 0 | K41: 0
C42: 0 | D42: 0 | E42: 0 | F42: 0 | G42: 0 | H42: 0 | I42: 0 | J42: 0 | K42: 0
C43: 0 | D43: 0 | E43: 0 | F43: 0 | G43: 0 | H43: 0 | I43: 0 | J43: 0 | K43: 0
A44: TOTAL | C44: =C16+C26+C35 -> 0 | D44: =D16+D26+D35 -> 0 | E44: =E16+E26+E35 -> 0 | F44: =F16+F26+F35 -> 0 | G44: =G16+G26+G35 -> 0 | H44: =H16+H26+H35 -> 0 | I44: =I16+I26+I35 -> 0 | J44: =J16+J26+J35 -> 0 | K44: =K16+K26+K35 -> 0
...

Sheet 30_70 (Millones)
A2: FO-70/30-01
A4: Cálculo y determinación del porcentaje del 30% a que se refiere el artículo 42 de
A5: la Ley de Adquisiciones, Arrendamientos y Servicios del Sector Público
A6: (Millones de pesos)
A7: Dependencia o Entidad: COMISION NACIONAL FORESTAL | I7: ='30_70 (Miles)'!I7:K7 -> Periodo: del 01 de enero al 31 de marzo 2020
A9: CONCEPTO | C9: PRESUPUESTO ANUAL AUTORIZADO | D9: CONTRATACIONES FORMALIZADAS CON CONTRATO FIRMADO
D10: ENTRE DEPENDENCIAS Y ENTIDADES | E10: ARTÍCULO 42 | G10: ARTÍCULO 41 | K10: LICITACIÓN PÚBLICA
A12: CLAVE | B12: DESCRIPCIÓN | C12: (Incluye modificaciones, en su caso) | E12: ADJUDICACIÓN DIRECTA | F12: INVITACIÓN A CUANDO MENOS TRES PERSONAS | G12: PATENTE | H12: COSTOS ADICIONALES | I12: MARCA DETERMINADA | J12: OTROS
D13: (Párrafo quinto del art.1 de la Ley) | K13: (Arts. 26, 26 Bis y 28 de la Ley)
G14: I | H14: III | I14: VIII | J14: II, IV a VII y IX a XX
C15: (A) | D15: (B) | E15: (C) | F15: (D) | G15: (E) | H15: (F) | I15: (G) | J15: (H) | K15: (I)
A16: CAPÍTULO 2000 - MATERIALES Y SUMINISTROS | C16: ='30_70 (Miles)'!C16/1000 -> 0 | D16: ='30_70 (Miles)'!D16/1000 -> 0 | E16: ='30_70 (Miles)'!E16/1000 -> 0 | F16: ='30_70 (Miles)'!F16/1000 -> 0 | G16: ='30_70 (Miles)'!G16/1000 -> 0 | H16: ='30_70 (Miles)'!H16/1000 -> 0 | I16: ='30_70 (Miles)'!I16/1000 -> 0 | J16: ='30_70 (Miles)'!J16/1000 -> 0 | K16: ='30_70 (Miles)'!K16/1000 -> 0
A17: ='30_70 (Miles)'!A17 -> 0 | B17: ='30_70 (Miles)'!B17 -> 0 | C17: ='30_70 (Miles)'!C17/1000 -> 0 | D17: ='30_70 (Miles)'!D17/1000 -> 0 | E17: ='30_70 (Miles)'!E17/1000 -> 0 | F17: ='30_70 (Miles)'!F17/1000 -> 0 | G17: ='30_70 (Miles)'!G17/1000 -> 0 | H17: ='30_70 (Miles)'!H17/1000 -> 0 | I17: ='30_70 (Miles)'!I17/1000 -> 0 | J17: ='30_70 (Miles)'!J17/1000 -> 0 | K17: ='30_70 (Miles)'!K17/1000 -> 0
A18: ='30_70 (Miles)'!A18 -> 0 | B18: ='30_70 (Miles)'!B18 -> 0 | C18: ='30_70 (Miles)'!C18/1000 -> 0 | D18: ='30_70 (Miles)'!D18/1000 -> 0 | E18: ='30_70 (Miles)'!E18/1000 -> 0 | F18: ='30_70 (Miles)'!F18/1000 -> 0 | G18: ='30_70 (Miles)'!G18/1000 -> 0 | H18: ='30_70 (Miles)'!H18/1000 -> 0 | I18: ='30_70 (Miles)'!I18/1000 -> 0 | J18: ='30_70 (Miles)'!J18/1000 -> 0 | K18: ='30_70 (Miles)'!K18/1000 -> 0
A19: ='30_70 (Miles)'!A19 -> 0 | B19: ='30_70 (Miles)'!B19 -> 0 | C19: ='30_70 (Miles)'!C19/1000 -> 0 | D19: ='30_70 (Miles)'!D19/1000 -> 0 | E19: ='30_70 (Miles)'!E19/1000 -> 0 | F19: ='30_70 (Miles)'!F19/1000 -> 0 | G19: ='30_70 (Miles)'!G19/1000 -> 0 | H19: ='30_70 (Miles)'!H19/1000 -> 0 | I19: ='30_70 (Miles)'!I19/1000 -> 0 | J19: ='30_70 (Miles)'!J19/1000 -> 0 | K19: ='30_70 (Miles)'!K19/1000 -> 0
A20: ='30_70 (Miles)'!A20 -> 0 | B20: ='30_70 (Miles)'!B20 -> 0 | C20: ='30_70 (Miles)'!C20/1000 -> 0 | D20: ='30_70 (Miles)'!D20/1000 -> 0 | E20: ='30_70 (Miles)'!E20/1000 -> 0 | F20: ='30_70 (Miles)'!F20/1000 -> 0 | G20: ='30_70 (Miles)'!G20/1000 -> 0 | H20: ='30_70 (Miles)'!H20/1000 -> 0 | I20: ='30_70 (Miles)'!I20/1000 -> 0 | J20: ='30_70 (Miles)'!J20/1000 -> 0 | K20: ='30_70 (Miles)'!K20/1000 -> 0
A21: ='30_70 (Miles)'!A21 -> 0 | B21: ='30_70 (Miles)'!B21 -> 0 | C21: ='30_70 (Miles)'!C21/1000 -> 0 | D21: ='30_70 (Miles)'!D21/1000 -> 0 | E21: ='30_70 (Miles)'!E21/1000 -> 0 | F21: ='30_70 (Miles)'!F21/1000 -> 0 | G21: ='30_70 (Miles)'!G21/1000 -> 0 | H21: ='30_70 (Miles)'!H21/1000 -> 0 | I21: ='30_70 (Miles)'!I21/1000 -> 0 | J21: ='30_70 (Miles)'!J21/1000 -> 0 | K21: ='30_70 (Miles)'!K21/1000 -> 0
A22: ='30_70 (Miles)'!A22 -> 0 | B22: ='30_70 (Miles)'!B22 -> 0 | C22: ='30_70 (Miles)'!C22/1000 -> 0 | D22: ='30_70 (Miles)'!D22/1000 -> 0 | E22: ='30_70 (Miles)'!E22/1000 -> 0 | F22: ='30_70 (Miles)'!F22/1000 -> 0 | G22: ='30_70 (Miles)'!G22/1000 -> 0 | H22: ='30_70 (Miles)'!H22/1000 -> 0 | I22: ='30_70 (Miles)'!I22/1000 -> 0 | J22: ='30_70 (Miles)'!J22/1000 -> 0 | K22: ='30_70 (Miles)'!K22/1000 -> 0
A23: ='30_70 (Miles)'!A23 -> 0 | B23: ='30_70 (Miles)'!B23 -> 0 | C23: ='30_70 (Miles)'!C23/1000 -> 0 | D23: ='30_70 (Miles)'!D23/1000 -> 0 | E23: ='30_70 (Miles)'!E23/1000 -> 0 | F23: ='30_70 (Miles)'!F23/1000 -> 0 | G23: ='30_70 (Miles)'!G23/1000 -> 0 | H23: ='30_70 (Miles)'!H23/1000 -> 0 | I23: ='30_70 (Miles)'!I23/1000 -> 0 | J23: ='30_70 (Miles)'!J23/1000 -> 0 | K23: ='30_70 (Miles)'!K23/1000 -> 0
A24: ='30_70 (Miles)'!A24 -> 0 | B24: ='30_70 (Miles)'!B24 -> 0 | C24: ='30_70 (Miles)'!C24/1000 -> 0 | D24: ='30_70 (Miles)'!D24/1000 -> 0 | E24: ='30_70 (Miles)'!E24/1000 -> 0 | F24: ='30_70 (Miles)'!F24/1000 -> 0 | G24: ='30_70 (Miles)'!G24/1000 -> 0 | H24: ='30_70 (Miles)'!H24/1000 -> 0 | I24: ='30_70 (Miles)'!I24/1000 -> 0 | J24: ='30_70 (Miles)'!J24/1000 -> 0 | K24: ='30_70 (Miles)'!K24/1000 -> 0
A25: ='30_70 (Miles)'!A25 -> 0 | B25: ='30_70 (Miles)'!B25 -> 0 | C25: ='30_70 (Miles)'!C25/1000 -> 0 | D25: ='30_70 (Miles)'!D25/1000 -> 0 | E25: ='30_70 (Miles)'!E25/1000 -> 0 | F25: ='30_70 (Miles)'!F25/1000 -> 0 | G25: ='30_70 (Miles)'!G25/1000 -> 0 | H25: ='30_70 (Miles)'!H25/1000 -> 0 | I25: ='30_70 (Miles)'!I25/1000 -> 0 | J25: ='30_70 (Miles)'!J25/1000 -> 0 | K25: ='30_70 (Miles)'!K25/1000 -> 0
A26: CAPÍTULO 3000 - SERVICIOS GENERALES (Excepto el Concepto 3900) | C26: ='30_70 (Miles)'!C26/1000 -> 0 | D26: ='30_70 (Miles)'!D26/1000 -> 0 | E26: ='30_70 (Miles)'!E26/1000 -> 0 | F26: ='30_70 (Miles)'!F26/1000 -> 0 | G26: ='30_70 (Miles)'!G26/1000 -> 0 | H26: ='30_70 (Miles)'!H26/1000 -> 0 | I26: ='30_70 (Miles)'!I26/1000 -> 0 | J26: ='30_70 (Miles)'!J26/1000 -> 0 | K26: ='30_70 (Miles)'!K26/1000 -> 0
A27: ='30_70 (Miles)'!A27 -> 0 | B27: ='30_70 (Miles)'!B27 -> 0 | C27: ='30_70 (Miles)'!C27/1000 -> 0 | D27: ='30_70 (Miles)'!D27/1000 -> 0 | E27: ='30_70 (Miles)'!E27/1000 -> 0 | F27: ='30_70 (Miles)'!F27/1000 -> 0 | G27: ='30_70 (Miles)'!G27/1000 -> 0 | H27: ='30_70 (Miles)'!H27/1000 -> 0 | I27: ='30_70 (Miles)'!I27/1000 -> 0 | J27: ='30_70 (Miles)'!J27/1000 -> 0 | K27: ='30_70 (Miles)'!K27/1000 -> 0
A28: ='30_70 (Miles)'!A28 -> 0 | B28: ='30_70 (Miles)'!B28 -> 0 | C28: ='30_70 (Miles)'!C28/1000 -> 0 | D28: ='30_70 (Miles)'!D28/1000 -> 0 | E28: ='30_70 (Miles)'!E28/1000 -> 0 | F28: ='30_70 (Miles)'!F28/1000 -> 0 | G28: ='30_70 (Miles)'!G28/1000 -> 0 | H28: ='30_70 (Miles)'!H28/1000 -> 0 | I28: ='30_70 (Miles)'!I28/1000 -> 0 | J28: ='30_70 (Miles)'!J28/1000 -> 0 | K28: ='30_70 (Miles)'!K28/1000 -> 0
A29: ='30_70 (Miles)'!A29 -> 0 | B29: ='30_70 (Miles)'!B29 -> 0 | C29: ='30_70 (Miles)'!C29/1000 -> 0 | D29: ='30_70 (Miles)'!D29/1000 -> 0 | E29: ='30_70 (Miles)'!E29/1000 -> 0 | F29: ='30_70 (Miles)'!F29/1000 -> 0 | G29: ='30_70 (Miles)'!G29/1000 -> 0 | H29: ='30_70 (Miles)'!H29/1000 -> 0 | I29: ='30_70 (Miles)'!I29/1000 -> 0 | J29: ='30_70 (Miles)'!J29/1000 -> 0 | K29: ='30_70 (Miles)'!K29/1000 -> 0
A30: ='30_70 (Miles)'!A30 -> 0 | B30: ='30_70 (Miles)'!B30 -> 0 | C30: ='30_70 (Miles)'!C30/1000 -> 0 | D30: ='30_70 (Miles)'!D30/1000 -> 0 | E30: ='30_70 (Miles)'!E30/1000 -> 0 | F30: ='30_70 (Miles)'!F30/1000 -> 0 | G30: ='30_70 (Miles)'!G30/1000 -> 0 | H30: ='30_70 (Miles)'!H30/1000 -> 0 | I30: ='30_70 (Miles)'!I30/1000 -> 0 | J30: ='30_70 (Miles)'!J30/1000 -> 0 | K30: ='30_70 (Miles)'!K30/1000 -> 0
A31: ='30_70 (Miles)'!A31 -> 0 | B31: ='30_70 (Miles)'!B31 -> 0 | C31: ='30_70 (Miles)'!C31/1000 -> 0 | D31: ='30_70 (Miles)'!D31/1000 -> 0 | E31: ='30_70 (Miles)'!E31/1000 -> 0 | F31: ='30_70 (Miles)'!F31/1000 -> 0 | G31: ='30_70 (Miles)'!G31/1000 -> 0 | H31: ='30_70 (Miles)'!H31/1000 -> 0 | I31: ='30_70 (Miles)'!I31/1000 -> 0 | J31: ='30_70 (Miles)'!J31/1000 -> 0 | K31: ='30_70 (Miles)'!K31/1000 -> 0
A32: ='30_70 (Miles)'!A32 -> 0 | B32: ='30_70 (Miles)'!B32 -> 0 | C32: ='30_70 (Miles)'!C32/1000 -> 0 | D32: ='30_70 (Miles)'!D32/1000 -> 0 | E32: ='30_70 (Miles)'!E32/1000 -> 0 | F32: ='30_70 (Miles)'!F32/1000 -> 0 | G32: ='30_70 (Miles)'!G32/1000 -> 0 | H32: ='30_70 (Miles)'!H32/1000 -> 0 | I32: ='30_70 (Miles)'!I32/1000 -> 0 | J32: ='30_70 (Miles)'!J32/1000 -> 0 | K32: ='30_70 (Miles)'!K32/1000 -> 0
A33: ='30_70 (Miles)'!A33 -> 0 | B33: ='30_70 (Miles)'!B33 -> 0 | C33: ='30_70 (Miles)'!C33/1000 -> 0 | D33: ='30_70 (Miles)'!D33/1000 -> 0 | E33: ='30_70 (Miles)'!E33/1000 -> 0 | F33: ='30_70 (Miles)'!F33/1000 -> 0 | G33: ='30_70 (Miles)'!G33/1000 -> 0 | H33: ='30_70 (Miles)'!H33/1000 -> 0 | I33: ='30_70 (Miles)'!I33/1000 -> 0 | J33: ='30_70 (Miles)'!J33/1000 -> 0 | K33: ='30_70 (Miles)'!K33/1000 -> 0
A34: ='30_70 (Miles)'!A34 -> 0 | B34: ='30_70 (Miles)'!B34 -> 0 | C34: ='30_70 (Miles)'!C34/1000 -> 0 | D34: ='30_70 (Miles)'!D34/1000 -> 0 | E34: ='30_70 (Miles)'!E34/1000 -> 0 | F34: ='30_70 (Miles)'!F34/1000 -> 0 | G34: ='30_70 (Miles)'!G34/1000 -> 0 | H34: ='30_70 (Miles)'!H34/1000 -> 0 | I34: ='30_70 (Miles)'!I34/1000 -> 0 | J34: ='30_70 (Miles)'!J34/1000 -> 0 | K34: ='30_70 (Miles)'!K34/1000 -> 0
A35: CAPÍTULO 5000 - BIENES MUEBLES, INMUEBLES E INTANGIBLES (Excepto el concepto 5800) | C35: ='30_70 (Miles)'!C35/1000 -> 0 | D35: ='30_70 (Miles)'!D35/1000 -> 0 | E35: ='30_70 (Miles)'!E35/1000 -> 0 | F35: ='30_70 (Miles)'!F35/1000 -> 0 | G35: ='30_70 (Miles)'!G35/1000 -> 0 | H35: ='30_70 (Miles)'!H35/1000 -> 0 | I35: ='30_70 (Miles)'!I35/1000 -> 0 | J35: ='30_70 (Miles)'!J35/1000 -> 0 | K35: ='30_70 (Miles)'!K35/1000 -> 0
A36: ='30_70 (Miles)'!A36 -> 0 | B36: ='30_70 (Miles)'!B36 -> 0 | C36: ='30_70 (Miles)'!C36/1000 -> 0 | D36: ='30_70 (Miles)'!D36/1000 -> 0 | E36: ='30_70 (Miles)'!E36/1000 -> 0 | F36: ='30_70 (Miles)'!F36/1000 -> 0 | G36: ='30_70 (Miles)'!G36/1000 -> 0 | H36: ='30_70 (Miles)'!H36/1000 -> 0 | I36: ='30_70 (Miles)'!I36/1000 -> 0 | J36: ='30_70 (Miles)'!J36/1000 -> 0 | K36: ='30_70 (Miles)'!K36/1000 -> 0
A37: ='30_70 (Miles)'!A37 -> 0 | B37: ='30_70 (Miles)'!B37 -> 0 | C37: ='30_70 (Miles)'!C37/1000 -> 0 | D37: ='30_70 (Miles)'!D37/1000 -> 0 | E37: ='30_70 (Miles)'!E37/1000 -> 0 | F37: ='30_70 (Miles)'!F37/1000 -> 0 | G37: ='30_70 (Miles)'!G37/1000 -> 0 | H37: ='30_70 (Miles)'!H37/1000 -> 0 | I37: ='30_70 (Miles)'!I37/1000 -> 0 | J37: ='30_70 (Miles)'!J37/1000 -> 0 | K37: ='30_70 (Miles)'!K37/1000 -> 0
A38: ='30_70 (Miles)'!A38 -> 0 | B38: ='30_70 (Miles)'!B38 -> 0 | C38: ='30_70 (Miles)'!C38/1000 -> 0 | D38: ='30_70 (Miles)'!D38/1000 -> 0 | E38: ='30_70 (Miles)'!E38/1000 -> 0 | F38: ='30_70 (Miles)'!F38/1000 -> 0 | G38: ='30_70 (Miles)'!G38/1000 -> 0 | H38: ='30_70 (Miles)'!H38/1000 -> 0 | I38: ='30_70 (Miles)'!I38/1000 -> 0 | J38: ='30_70 (Miles)'!J38/1000 -> 0 | K38: ='30_70 (Miles)'!K38/1000 -> 0
A39: ='30_70 (Miles)'!A39 -> 0 | B39: ='30_70 (Miles)'!B39 -> 0 | C39: ='30_70 (Miles)'!C39/1000 -> 0 | D39: ='30_70 (Miles)'!D39/1000 -> 0 | E39: ='30_70 (Miles)'!E39/1000 -> 0 | F39: ='30_70 (Miles)'!F39/1000 -> 0 | G39: ='30_70 (Miles)'!G39/1000 -> 0 | H39: ='30_70 (Miles)'!H39/1000 -> 0 | I39: ='30_70 (Miles)'!I39/1000 -> 0 | J39: ='30_70 (Miles)'!J39/1000 -> 0 | K39: ='30_70 (Miles)'!K39/1000 -> 0
A40: ='30_70 (Miles)'!A40 -> 0 | B40: ='30_70 (Miles)'!B40 -> 0 | C40: ='30_70 (Miles)'!C40/1000 -> 0 | D40: ='30_70 (Miles)'!D40/1000 -> 0 | E40: ='30_70 (Miles)'!E40/1000 -> 0 | F40: ='30_70 (Miles)'!F40/1000 -> 0 | G40: ='30_70 (Miles)'!G40/1000 -> 0 | H40: ='30_70 (Miles)'!H40/1000 -> 0 | I40: ='30_70 (Miles)'!I40/1000 -> 0 | J40: ='30_70 (Miles)'!J40/1000 -> 0 | K40: ='30_70 (Miles)'!K40/1000 -> 0
A41: ='30_70 (Miles)'!A41 -> 0 | B41: ='30_70 (Miles)'!B41 -> 0 | C41: ='30_70 (Miles)'!C41/1000 -> 0 | D41: ='30_70 (Miles)'!D41/1000 -> 0 | E41: ='30_70 (Miles)'!E41/1000 -> 0 | F41: ='30_70 (Miles)'!F41/1000 -> 0 | G41: ='30_70 (Miles)'!G41/1000 -> 0 | H41: ='30_70 (Miles)'!H41/1000 -> 0 | I41: ='30_70 (Miles)'!I41/1000 -> 0 | J41: ='30_70 (Miles)'!J41/1000 -> 0 | K41: ='30_70 (Miles)'!K41/1000 -> 0
A42: ='30_70 (Miles)'!A42 -> 0 | B42: ='30_70 (Miles)'!B42 -> 0 | C42: ='30_70 (Miles)'!C42/1000 -> 0 | D42: ='30_70 (Miles)'!D42/1000 -> 0 | E42: ='30_70 (Miles)'!E42/1000 -> 0 | F42: ='30_70 (Miles)'!F42/1000 -> 0 | G42: ='30_70 (Miles)'!G42/1000 -> 0 | H42: ='30_70 (Miles)'!H42/1000 -> 0 | I42: ='30_70 (Miles)'!I42/1000 -> 0 | J42: ='30_70 (Miles)'!J42/1000 -> 0 | K42: ='30_70 (Miles)'!K42/1000 -> 0
A43: ='30_70 (Miles)'!A43 -> 0 | B43: ='30_70 (Miles)'!B43 -> 0 | C43: ='30_70 (Miles)'!C43/1000 -> 0 | D43: ='30_70 (Miles)'!D43/1000 -> 0 | E43: ='30_70 (Miles)'!E43/1000 -> 0 | F43: ='30_70 (Miles)'!F43/1000 -> 0 | G43: ='30_70 (Miles)'!G43/1000 -> 0 | H43: ='30_70 (Miles)'!H43/1000 -> 0 | I43: ='30_70 (Miles)'!I43/1000 -> 0 | J43: ='30_70 (Miles)'!J43/1000 -> 0 | K43: ='30_70 (Miles)'!K43/1000 -> 0
A44: TOTAL | C44: ='30_70 (Miles)'!C44/1000 -> 0 | D44: ='30_70 (Miles)'!D44/1000 -> 0 | E44: ='30_70 (Miles)'!E44/1000 -> 0 | F44: ='30_70 (Miles)'!F44/1000 -> 0 | G44: ='30_70 (Miles)'!G44/1000 -> 0 | H44: ='30_70 (Miles)'!H44/1000 -> 0 | I44: ='30_70 (Miles)'!I44/1000 -> 0 | J44: ='30_70 (Miles)'!J44/1000 -> 0 | K44: ='30_70 (Miles)'!K44/1000 -> 0
...

Sheet Contratos
A1: Contrato SAI | B1: Fundamento Legal | C1: Partida Presupuestal | D1: Contrato CNET | E1: Fecha Inicio | F1: Fecha Fin | G1: Fecha Formalización | H1: RFC | I1: Razón Social | J1: Concepto | K1: Código Contrato | L1: Código Expediente | M1: Total Contratado Con IVA

Sheet Pedidos
A1: Pedido SAI | B1: Fundamento Legal | C1: Partida Presupuestal | D1: Contrato CNET | E1: Fecha Inicio | F1: Fecha Fin | G1: Fecha Formalización | H1: RFC | I1: Razón Social | J1: Concepto | K1: Código Contrato | L1: Código Expediente | M1: Total Pedido Con IVA

Sheet PagosDirectos
A1: Folio de Pago | B1: Contrarecibo | C1: Concepto | D1: Área | E1: RFC | F1: Razón Social | G1: Partida Presupuestal | H1: Monto Total Con IVA

Sheet Excepciones
A1: Excepto las partidas
A2: 390 | B2: Excepto | C2: (Excepto el Concepto 3900)
A3: 391 | B3: Excepto
A4: 392 | B4: Excepto
A5: 393 | B5: Excepto
A6: 394 | B6: Excepto
A7: 395 | B7: Excepto
A8: 396 | B8: Excepto
A9: 397 | B9: Excepto
A10: 398 | B10: Excepto
A11: 399 | B11: Excepto
A12: 321 | B12: Excepto | C12: (Excepto las partidas 321 y 322)
A13: 322 | B13: Excepto
A14: 341 | B14: Excepto | C14: (Excepto las partidas 341, 343 y 349)
A15: 343 | B15: Excepto
A16: 349 | B16: Excepto
A17: 351 | B17: Excepto | C17: (Excepto la partida 351)
A18: 375 | B18: Excepto | C18: (Excepto las partidas 375 a 379)
A19: 376 | B19: Excepto
A20: 377 | B20: Excepto
A21: 378 | B21: Excepto
A22: 379 | B22: Excepto
A23: 580 | B23: Excepto | C23: (Excepto el concepto 5800)
A24: 581 | B24: Excepto
A25: 582 | B25: Excepto
A26: 583 | B26: Excepto
A27: 584 | B27: Excepto
A28: 585 | B28: Excepto
A29: 586 | B29: Excepto
A30: 587 | B30: Excepto
A31: 588 | B31: Excepto
A32: 589 | B32: Excepto
A33: 590 | B33: Excepto
A34: 592 | B34: Excepto | C34: (Excepto las partidas 592 a 596 y 598)
A35: 593 | B35: Excepto
A36: 594 | B36: Excepto
A37: 595 | B37: Excepto
A38: 596 | B38: Excepto
A39: 598 | B39: Excepto

Sheet exepciones
A1: Excepto el concepto 5800
A2: Excepto las partidas 341, 343 y 349
A3: Excepto el Concepto 3900
A4: Excepto la partida 351
A5: Excepto las partidas 321 y 322
A6: Excepto las partidas 375 a 379
A7: Excepto las partidas 592 a 596 y 598
B8: presupuesto
B9: 21 | C9: 39739503
B10: 22 | C10: 13316794
B11: 23 | C11: 4640149.4
B12: 24 | C12: 12066863
B13: 25 | C13: 6843171.2
B14: 26 | C14: 25130462
B15: 27 | C15: 86132433
B17: 29 | C17: 29613429
B19: 31 | C19: 48315775
B20: 32 | C20: 95483494
B21: 33 | C21: 2.2583937e+08
B22: 34 | C22: 56875979
... B33: 56 | C33: 816727.96

Sheet consideraciones
B2: Excepciones del presupeusto proporcionado
B4: MODIFICADO ANUAL MARZO
B5: 32 | C5: 18340038
B6: 34 | C6: 10074.32
B7: 35 | C7: 1481117.4
B8: 37 | C8: 71824233
B9: 39 | C9: 34346344
B10: Total general | C10: 1.2600181e+08
B12: Del reporte de ordenes de compra se consideran lo siguiente:
B14: Solamente se ingresan registros con fecha de incicio que abarcan el prier trimestre
B15: Monto minimo con iva incluido
B16: Y se modifican los articulos de la base de datos conforme a la relación de contratos de alfredo
B17: Se realizan las excepciones correspondientes del formato
B18: Se consideran Contratos Plurianuales y solo el importe del ejercicio
